Workbook

Sheet Roster
A1: Player | B1: Team | C1: Nationality / origin | D1: Suggested OVR | E1: Positions (GK / DF / MF / OF) | F1: Anime arc | G1: Verification | H1: GK | I1: DF | J1: MF | K1: OF | L1: Portrait | M1: Team Wiki Page | N1: Portrait URL | O1: Portrait source | P1: Sprite verification | Q1: Sprite wiki reference | R1: Canonical Name
A2: Endou Mamoru | B2: Raimon | C2: Japan | D2: 94 | E2: GK, DF | F2: Original / Season 1 | G2: Prototype (unverified) | H2: TRUE | I2: TRUE | J2: FALSE | K2: FALSE | L2: =IF(N2="","",IFERROR(IMAGE(N2,4,48,48),"")) | M2: =IF(B2="","",IFERROR(VLOOKUP(B2,'Team Lineups'!$A$2:$Q$123,17,FALSE),"")) -> https://inazuma-eleven.fandom.com/wiki/Raimon | N2: https://static.wikia.nocookie.net/inazuma-eleven/images/3/32/(R_IE2-IE3)_Endou_Mamoru_sprite.png/revision/latest | O2: Inazuma Eleven Wiki · (R IE2-IE3) Endou Mamoru sprite.png | P2: Earlier wiki sprite mapping — verify image
A3: Kazemaru Ichirouta | B3: Raimon | C3: Japan | D3: 87 | E3: DF, MF, OF | F3: Original / Season 1 | G3: Prototype (unverified) | H3: FALSE | I3: TRUE | J3: TRUE | K3: TRUE | L3: =IF(N3="","",IFERROR(IMAGE(N3,4,48,48),"")) | M3: =IF(B3="","",IFERROR(VLOOKUP(B3,'Team Lineups'!$A$2:$Q$123,17,FALSE),"")) -> https://inazuma-eleven.fandom.com/wiki/Raimon | N3: https://static.wikia.nocookie.net/inazuma-eleven/images/7/72/(R_IE2-IE3)_Kazemaru_Ichirouta_sprite.png/revision/latest | O3: Inazuma Eleven Wiki · (R IE2-IE3) Kazemaru Ichirouta sprite.png | P3: Earlier wiki sprite mapping — verify image
A4: Kabeyama Heigorou | B4: Raimon | C4: Japan | D4: 84 | E4: DF | F4: Original / Season 1 | G4: Prototype (unverified) | H4: FALSE | I4: TRUE | J4: FALSE | K4: FALSE | L4: =IF(N4="","",IFERROR(IMAGE(N4,4,48,48),"")) | M4: =IF(B4="","",IFERROR(VLOOKUP(B4,'Team Lineups'!$A$2:$Q$123,17,FALSE),"")) -> https://inazuma-eleven.fandom.com/wiki/Raimon | N4: https://static.wikia.nocookie.net/inazuma-eleven/images/b/ba/(R_IE2-IE3)_Kabeyama_Heigorou_sprite.png/revision/latest | O4: Inazuma Eleven Wiki · (R IE2-IE3) Kabeyama Heigorou sprite.png | P4: Earlier wiki sprite mapping — verify image
A5: Kageno Jin | B5: Raimon | C5: Japan | D5: 76 | E5: DF | F5: Original / Season 1 | G5: Added (verify team/roster) | H5: FALSE | I5: TRUE | J5: FALSE | K5: FALSE | L5: =IF(N5="","",IFERROR(IMAGE(N5,4,48,48),"")) | M5: =IF(B5="","",IFERROR(VLOOKUP(B5,'Team Lineups'!$A$2:$Q$123,17,FALSE),"")) -> https://inazuma-eleven.fandom.com/wiki/Raimon | N5: https://static.wikia.nocookie.net/inazuma-eleven/images/9/9b/(R_IE2-IE3)_Kageno_Jin_sprite.png/revision/latest | O5: Inazuma Eleven Wiki · (R IE2-IE3) Kageno Jin sprite.png | P5: Earlier wiki sprite mapping — verify image
A6: Kurimatsu Teppei | B6: Raimon | C6: Japan | D6: 79 | E6: DF, MF | F6: Original / Season 1 | G6: Prototype (unverified) | H6: FALSE | I6: TRUE | J6: TRUE | K6: FALSE | L6: =IF(N6="","",IFERROR(IMAGE(N6,4,48,48),"")) | M6: =IF(B6="","",IFERROR(VLOOKUP(B6,'Team Lineups'!$A$2:$Q$123,17,FALSE),"")) -> https://inazuma-eleven.fandom.com/wiki/Raimon | N6: https://static.wikia.nocookie.net/inazuma-eleven/images/9/97/(R_IE2-IE3)_Kurimatsu_Teppei_sprite.png/revision/latest | O6: Inazuma Eleven Wiki · (R IE2-IE3) Kurimatsu Teppei sprite.png | P6: Earlier wiki sprite mapping — verify image
A7: Handa Shinichi | B7: Raimon | C7: Japan | D7: 77 | E7: MF | F7: Original / Season 1 | G7: Prototype (unverified) | H7: FALSE | I7: FALSE | J7: TRUE | K7: FALSE | L7: =IF(N7="","",IFERROR(IMAGE(N7,4,48,48),"")) | M7: =IF(B7="","",IFERROR(VLOOKUP(B7,'Team Lineups'!$A$2:$Q$123,17,FALSE),"")) -> https://inazuma-eleven.fandom.com/wiki/Raimon | N7: https://static.wikia.nocookie.net/inazuma-eleven/images/0/04/(R_IE2-IE3)_Handa_Shinichi_sprite.png/revision/latest | O7: Inazuma Eleven Wiki · (R IE2-IE3) Handa Shinichi sprite.png | P7: Earlier wiki sprite mapping — verify image
A8: Shourinji Ayumu | B8: Raimon | C8: Japan | D8: 76 | E8: DF, MF | F8: Original / Season 1 | G8: Prototype (unverified) | H8: FALSE | I8: TRUE | J8: TRUE | K8: FALSE | L8: =IF(N8="","",IFERROR(IMAGE(N8,4,48,48),"")) | M8: =IF(B8="","",IFERROR(VLOOKUP(B8,'Team Lineups'!$A$2:$Q$123,17,FALSE),"")) -> https://inazuma-eleven.fandom.com/wiki/Raimon | N8: https://static.wikia.nocookie.net/inazuma-eleven/images/4/41/(R_IE2-IE3)_Shourinji_Ayumu_sprite.png/revision/latest | O8: Inazuma Eleven Wiki · (R IE2-IE3) Shourinji Ayumu sprite.png | P8: Earlier wiki sprite mapping — verify image
A9: Shishido Sakichi | B9: Raimon | C9: Japan | D9: 75 | E9: DF, MF | F9: Original / Season 1 | G9: Added (verify team/roster) | H9: FALSE | I9: TRUE | J9: TRUE | K9: FALSE | L9: =IF(N9="","",IFERROR(IMAGE(N9,4,48,48),"")) | M9: =IF(B9="","",IFERROR(VLOOKUP(B9,'Team Lineups'!$A$2:$Q$123,17,FALSE),"")) -> https://inazuma-eleven.fandom.com/wiki/Raimon | N9: https://static.wikia.nocookie.net/inazuma-eleven/images/5/58/(R_IE2-IE3)_Shishido_Sakichi_sprite.png/revision/latest | O9: Inazuma Eleven Wiki · (R IE2-IE3) Shishido Sakichi sprite.png | P9: Earlier wiki sprite mapping — verify image
A10: Matsuno Kuusuke | B10: Raimon | C10: Japan | D10: 79 | E10: MF, OF | F10: Original / Season 1 | G10: Added (verify team/roster) | H10: FALSE | I10: FALSE | J10: TRUE | K10: TRUE | L10: =IF(N10="","",IFERROR(IMAGE(N10,4,48,48),"")) | M10: =IF(B10="","",IFERROR(VLOOKUP(B10,'Team Lineups'!$A$2:$Q$123,17,FALSE),"")) -> https://inazuma-eleven.fandom.com/wiki/Raimon | N10: https://static.wikia.nocookie.net/inazuma-eleven/images/9/91/(R_IE2-IE3)_Matsuno_Kuusuke_sprite.png/revision/latest | O10: Inazuma Eleven Wiki · (R IE2-IE3) Matsuno Kuusuke sprite.png | P10: Earlier wiki sprite mapping — verify image
A11: Gouenji Shuuya | B11: Raimon | C11: Japan | D11: 95 | E11: OF | F11: Original / Season 1 | G11: Prototype (unverified) | H11: FALSE | I11: FALSE | J11: FALSE | K11: TRUE | L11: =IF(N11="","",IFERROR(IMAGE(N11,4,48,48),"")) | M11: =IF(B11="","",IFERROR(VLOOKUP(B11,'Team Lineups'!$A$2:$Q$123,17,FALSE),"")) -> https://inazuma-eleven.fandom.com/wiki/Raimon | N11: https://static.wikia.nocookie.net/inazuma-eleven/images/b/b8/(R_IE2-IE3)_Gouenji_Shuuya_sprite.png/revision/latest | O11: Inazuma Eleven Wiki · (R IE2-IE3) Gouenji Shuuya sprite.png | P11: Earlier wiki sprite mapping — verify image
A12: Someoka Ryuugo | B12: Raimon | C12: Japan | D12: 84 | E12: OF | F12: Original / Season 1 | G12: Prototype (unverified) | H12: FALSE | I12: FALSE | J12: FALSE | K12: TRUE | L12: =IF(N12="","",IFERROR(IMAGE(N12,4,48,48),"")) | M12: =IF(B12="","",IFERROR(VLOOKUP(B12,'Team Lineups'!$A$2:$Q$123,17,FALSE),"")) -> https://inazuma-eleven.fandom.com/wiki/Raimon | N12: https://static.wikia.nocookie.net/inazuma-eleven/images/7/72/(R_IE2-IE3)_Someoka_Ryuugo_sprite.png/revision/latest | O12: Inazuma Eleven Wiki · (R IE2-IE3) Someoka Ryuugo sprite.png | P12: Earlier wiki sprite mapping — verify image
A13: Megane Kakeru | B13: Raimon | C13: Japan | D13: 68 | E13: DF, OF | F13: Original / Season 1 | G13: Added (verify team/roster) | H13: FALSE | I13: TRUE | J13: FALSE | K13: TRUE | L13: =IF(N13="","",IFERROR(IMAGE(N13,4,48,48),"")) | M13: =IF(B13="","",IFERROR(VLOOKUP(B13,'Team Lineups'!$A$2:$Q$123,17,FALSE),"")) -> https://inazuma-eleven.fandom.com/wiki/Raimon | N13: https://static.wikia.nocookie.net/inazuma-eleven/images/2/2b/(R_IE2-IE3)_Megane_Kakeru_sprite.png/revision/latest | O13: Inazuma Eleven Wiki · (R IE2-IE3) Megane Kakeru sprite.png | P13: Earlier wiki sprite mapping — verify image
A14: Domon Asuka | B14: Raimon | C14: Japan | D14: 83 | E14: DF, MF | F14: Original / Season 1 | G14: Prototype (unverified) | H14: FALSE | I14: TRUE | J14: TRUE | K14: FALSE | L14: =IF(N14="","",IFERROR(IMAGE(N14,4,48,48),"")) | M14: =IF(B14="","",IFERROR(VLOOKUP(B14,'Team Lineups'!$A$2:$Q$123,17,FALSE),"")) -> https://inazuma-eleven.fandom.com/wiki/Raimon | N14: https://static.wikia.nocookie.net/inazuma-eleven/images/e/e1/(R_IE3)_Domon_Asuka_sprite.png/revision/latest | O14: Inazuma Eleven Wiki · (R IE3) Domon Asuka sprite.png | P14: Earlier wiki sprite mapping — verify image
A15: Kidou Yuuto | B15: Raimon | C15: Japan | D15: 94 | E15: MF, OF | F15: Original / Season 1 | G15: Prototype (unverified) | H15: FALSE | I15: FALSE | J15: TRUE | K15: TRUE | L15: =IF(N15="","",IFERROR(IMAGE(N15,4,48,48),"")) | M15: =IF(B15="","",IFERROR(VLOOKUP(B15,'Team Lineups'!$A$2:$Q$123,17,FALSE),"")) -> https://inazuma-eleven.fandom.com/wiki/Raimon | N15: https://static.wikia.nocookie.net/inazuma-eleven/images/a/a0/(R_IE2-IE3)_Kidou_Yuuto_sprite.png/revision/latest | O15: Inazuma Eleven Wiki · (R IE2-IE3) Kidou Yuuto sprite.png | P15: Earlier wiki sprite mapping — verify image
A16: Ichinose Kazuya | B16: Raimon | C16: Japan | D16: 90 | E16: MF | F16: Original / Season 1 | G16: Prototype (unverified) | H16: FALSE | I16: FALSE | J16: TRUE | K16: FALSE | L16: =IF(N16="","",IFERROR(IMAGE(N16,4,48,48),"")) | M16: =IF(B16="","",IFERROR(VLOOKUP(B16,'Team Lineups'!$A$2:$Q$123,17,FALSE),"")) -> https://inazuma-eleven.fandom.com/wiki/Raimon | N16: https://static.wikia.nocookie.net/inazuma-eleven/images/7/74/(R_IE2-IE3)_Ichinose_Kazuya_sprite.png/revision/latest | O16: Inazuma Eleven Wiki · (R IE2-IE3) Ichinose Kazuya sprite.png | P16: Earlier wiki sprite mapping — verify image
A17: Endou Mamoru | B17: Raimon A Team | C17: Japan | D17: 94 | E17: GK, DF | F17: Original / Season 1 | G17: Wiki documented member/reserve; OVR and role suggested | H17: TRUE | I17: TRUE | J17: FALSE | K17: FALSE | L17: =IF(N17="","",IFERROR(IMAGE(N17,4,48,48),"")) | M17: =IF(B17="","",IFERROR(VLOOKUP(B17,'Team Lineups'!$A$2:$Q$123,17,FALSE),"")) -> https://inazuma-eleven.fandom.com/wiki/Raimon | N17: https://static.wikia.nocookie.net/inazuma-eleven/images/3/32/(R_IE2-IE3)_Endou_Mamoru_sprite.png/revision/latest | O17: Inazuma Eleven Wiki · Reused portrait from source character; team appearance may vary | P17: Reused portrait from source character; team appearance may vary | Q17: Existing player sprite source | R17: Endou Mamoru
A18: Kazemaru Ichirouta | B18: Raimon A Team | C18: Japan | D18: 87 | E18: DF, MF, OF | F18: Original / Season 1 | G18: Wiki documented member/reserve; OVR and role suggested | H18: FALSE | I18: TRUE | J18: TRUE | K18: TRUE | L18: =IF(N18="","",IFERROR(IMAGE(N18,4,48,48),"")) | M18: =IF(B18="","",IFERROR(VLOOKUP(B18,'Team Lineups'!$A$2:$Q$123,17,FALSE),"")) -> https://inazuma-eleven.fandom.com/wiki/Raimon | N18: https://static.wikia.nocookie.net/inazuma-eleven/images/7/72/(R_IE2-IE3)_Kazemaru_Ichirouta_sprite.png/revision/latest | O18: Inazuma Eleven Wiki · Reused portrait from source character; team appearance may vary | P18: Reused portrait from source character; team appearance may vary | Q18: Existing player sprite source | R18: Kazemaru Ichirouta
A19: Kabeyama Heigorou | B19: Raimon A Team | C19: Japan | D19: 84 | E19: DF | F19: Original / Season 1 | G19: Wiki documented member/reserve; OVR and role suggested | H19: FALSE | I19: TRUE | J19: FALSE | K19: FALSE | L19: =IF(N19="","",IFERROR(IMAGE(N19,4,48,48),"")) | M19: =IF(B19="","",IFERROR(VLOOKUP(B19,'Team Lineups'!$A$2:$Q$123,17,FALSE),"")) -> https://inazuma-eleven.fandom.com/wiki/Raimon | N19: https://static.wikia.nocookie.net/inazuma-eleven/images/b/ba/(R_IE2-IE3)_Kabeyama_Heigorou_sprite.png/revision/latest | O19: Inazuma Eleven Wiki · Reused portrait from source character; team appearance may vary | P19: Reused portrait from source character; team appearance may vary | Q19: Existing player sprite source | R19: Kabeyama Heigorou
A20: Kageno Jin | B20: Raimon A Team | C20: Japan | D20: 76 | E20: DF | F20: Original / Season 1 | G20: Wiki documented member/reserve; OVR and role suggested | H20: FALSE | I20: TRUE | J20: FALSE | K20: FALSE | L20: =IF(N20="","",IFERROR(IMAGE(N20,4,48,48),"")) | M20: =IF(B20="","",IFERROR(VLOOKUP(B20,'Team Lineups'!$A$2:$Q$123,17,FALSE),"")) -> https://inazuma-eleven.fandom.com/wiki/Raimon | N20: https://static.wikia.nocookie.net/inazuma-eleven/images/9/9b/(R_IE2-IE3)_Kageno_Jin_sprite.png/revision/latest | O20: Inazuma Eleven Wiki · Reused portrait from source character; team appearance may vary | P20: Reused portrait from source character; team appearance may vary | Q20: Existing player sprite source | R20: Kageno Jin
A21: Kurimatsu Teppei | B21: Raimon A Team | C21: Japan | D21: 79 | E21: DF, MF | F21: Original / Season 1 | G21: Wiki documented member/reserve; OVR and role suggested | H21: FALSE | I21: TRUE | J21: TRUE | K21: FALSE | L21: =IF(N21="","",IFERROR(IMAGE(N21,4,48,48),"")) | M21: =IF(B21="","",IFERROR(VLOOKUP(B21,'Team Lineups'!$A$2:$Q$123,17,FALSE),"")) -> https://inazuma-eleven.fandom.com/wiki/Raimon | N21: https://static.wikia.nocookie.net/inazuma-eleven/images/9/97/(R_IE2-IE3)_Kurimatsu_Teppei_sprite.png/revision/latest | O21: Inazuma Eleven Wiki · Reused portrait from source character; team appearance may vary | P21: Reused portrait from source character; team appearance may vary | Q21: Existing player sprite source | R21: Kurimatsu Teppei
A22: Handa Shinichi | B22: Raimon A Team | C22: Japan | D22: 77 | E22: MF | F22: Original / Season 1 | G22: Wiki documented member/reserve; OVR and role suggested | H22: FALSE | I22: FALSE | J22: TRUE | K22: FALSE | L22: =IF(N22="","",IFERROR(IMAGE(N22,4,48,48),"")) | M22: =IF(B22="","",IFERROR(VLOOKUP(B22,'Team Lineups'!$A$2:$Q$123,17,FALSE),"")) -> https://inazuma-eleven.fandom.com/wiki/Raimon | N22: https://static.wikia.nocookie.net/inazuma-eleven/images/0/04/(R_IE2-IE3)_Handa_Shinichi_sprite.png/revision/latest | O22: Inazuma Eleven Wiki · Reused portrait from source character; team appearance may vary | P22: Reused portrait from source character; team appearance may vary | Q22: Existing player sprite source | R22: Handa Shinichi
A23: Shourinji Ayumu | B23: Raimon A Team | C23: Japan | D23: 76 | E23: DF, MF | F23: Original / Season 1 | G23: Wiki documented member/reserve; OVR and role suggested | H23: FALSE | I23: TRUE | J23: TRUE | K23: FALSE | L23: =IF(N23="","",IFERROR(IMAGE(N23,4,48,48),"")) | M23: =IF(B23="","",IFERROR(VLOOKUP(B23,'Team Lineups'!$A$2:$Q$123,17,FALSE),"")) -> https://inazuma-eleven.fandom.com/wiki/Raimon | N23: https://static.wikia.nocookie.net/inazuma-eleven/images/4/41/(R_IE2-IE3)_Shourinji_Ayumu_sprite.png/revision/latest | O23: Inazuma Eleven Wiki · Reused portrait from source character; team appearance may vary | P23: Reused portrait from source character; team appearance may vary | Q23: Existing player sprite source | R23: Shourinji Ayumu
A24: Shishido Sakichi | B24: Raimon A Team | C24: Japan | D24: 75 | E24: DF, MF | F24: Original / Season 1 | G24: Wiki documented member/reserve; OVR and role suggested | H24: FALSE | I24: TRUE | J24: TRUE | K24: FALSE | L24: =IF(N24="","",IFERROR(IMAGE(N24,4,48,48),"")) | M24: =IF(B24="","",IFERROR(VLOOKUP(B24,'Team Lineups'!$A$2:$Q$123,17,FALSE),"")) -> https://inazuma-eleven.fandom.com/wiki/Raimon | N24: https://static.wikia.nocookie.net/inazuma-eleven/images/5/58/(R_IE2-IE3)_Shishido_Sakichi_sprite.png/revision/latest | O24: Inazuma Eleven Wiki · Reused portrait from source character; team appearance may vary | P24: Reused portrait from source character; team appearance may vary | Q24: Existing player sprite source | R24: Shishido Sakichi
A25: Matsuno Kuusuke | B25: Raimon A Team | C25: Japan | D25: 79 | E25: MF, OF | F25: Original / Season 1 | G25: Wiki documented member/reserve; OVR and role suggested | H25: FALSE | I25: FALSE | J25: TRUE | K25: TRUE | L25: =IF(N25="","",IFERROR(IMAGE(N25,4,48,48),"")) | M25: =IF(B25="","",IFERROR(VLOOKUP(B25,'Team Lineups'!$A$2:$Q$123,17,FALSE),"")) -> https://inazuma-eleven.fandom.com/wiki/Raimon | N25: https://static.wikia.nocookie.net/inazuma-eleven/images/9/91/(R_IE2-IE3)_Matsuno_Kuusuke_sprite.png/revision/latest | O25: Inazuma Eleven Wiki · Reused portrait from source character; team appearance may vary | P25: Reused portrait from source character; team appearance may vary | Q25: Existing player sprite source | R25: Matsuno Kuusuke
A26: Gouenji Shuuya | B26: Raimon A Team | C26: Japan | D26: 95 | E26: OF | F26: Original / Season 1 | G26: Wiki documented member/reserve; OVR and role suggested | H26: FALSE | I26: FALSE | J26: FALSE | K26: TRUE | L26: =IF(N26="","",IFERROR(IMAGE(N26,4,48,48),"")) | M26: =IF(B26="","",IFERROR(VLOOKUP(B26,'Team Lineups'!$A$2:$Q$123,17,FALSE),"")) -> https://inazuma-eleven.fandom.com/wiki/Raimon | N26: https://static.wikia.nocookie.net/inazuma-eleven/images/b/b8/(R_IE2-IE3)_Gouenji_Shuuya_sprite.png/revision/latest | O26: Inazuma Eleven Wiki · Reused portrait from source character; team appearance may vary | P26: Reused portrait from source character; team appearance may vary | Q26: Existing player sprite source | R26: Gouenji Shuuya
A27: Someoka Ryuugo | B27: Raimon A Team | C27: Japan | D27: 84 | E27: OF | F27: Original / Season 1 | G27: Wiki documented member/reserve; OVR and role suggested | H27: FALSE | I27: FALSE | J27: FALSE | K27: TRUE | L27: =IF(N27="","",IFERROR(IMAGE(N27,4,48,48),"")) | M27: =IF(B27="","",IFERROR(VLOOKUP(B27,'Team Lineups'!$A$2:$Q$123,17,FALSE),"")) -> https://inazuma-eleven.fandom.com/wiki/Raimon | N27: https://static.wikia.nocookie.net/inazuma-eleven/images/7/72/(R_IE2-IE3)_Someoka_Ryuugo_sprite.png/revision/latest | O27: Inazuma Eleven Wiki · Reused portrait from source character; team appearance may vary | P27: Reused portrait from source character; team appearance may vary | Q27: Existing player sprite source | R27: Someoka Ryuugo
A28: Genda Koujirou | B28: Teikoku Gakuen | C28: Japan | D28: 88 | E28: GK | F28: Original / Season 1 | G28: Prototype (unverified) | H28: TRUE | I28: FALSE | J28: FALSE | K28: FALSE | L28: =IF(N28="","",IFERROR(IMAGE(N28,4,48,48),"")) | M28: =IF(B28="","",IFERROR(VLOOKUP(B28,'Team Lineups'!$A$2:$Q$123,17,FALSE),"")) -> https://inazuma-eleven.fandom.com/wiki/Teikoku_Gakuen | N28: https://static.wikia.nocookie.net/inazuma-eleven/images/1/12/%28TG_IE2-IE3%29_Genda_Koujirou_sprite.png/revision/latest?cb=20230827091508 | O28: Inazuma Eleven Wiki · (TG IE2-IE3) Genda Koujirou sprite.png | P28: Exact user-supplied wiki sprite — correct team uniform | Q28: https://inazuma-eleven.fandom.com/wiki/Genda_Koujirou
A29: Oono Densuke | B29: Teikoku Gakuen | C29: Japan | D29: 75 | E29: DF | F29: Original / Season 1 | G29: Added (verify team/roster) | H29: FALSE | I29: TRUE | J29: FALSE | K29: FALSE | L29: =IF(N29="","",IFERROR(IMAGE(N29,4,48,48),"")) | M29: =IF(B29="","",IFERROR(VLOOKUP(B29,'Team Lineups'!$A$2:$Q$123,17,FALSE),"")) -> https://inazuma-eleven.fandom.com/wiki/Teikoku_Gakuen | N29: https://static.wikia.nocookie.net/inazuma-eleven/images/9/9b/(TG)_Oono_Densuke_sprite.png/revision/latest | O29: Inazuma Eleven Wiki · (TG) Oono Densuke sprite.png · candidate (check image) | P29: Candidate URL — needs visual check
A30: Banjou Kazumichi | B30: Teikoku Gakuen | C30: Japan | D30: 78 | E30: DF | F30: Original / Season 1 | G30: Added (verify team/roster) | H30: FALSE | I30: TRUE | J30: FALSE | K30: FALSE | L30: =IF(N30="","",IFERROR(IMAGE(N30,4,48,48),"")) | M30: =IF(B30="","",IFERROR(VLOOKUP(B30,'Team Lineups'!$A$2:$Q$123,17,FALSE),"")) -> https://inazuma-eleven.fandom.com/wiki/Teikoku_Gakuen | N30: https://static.wikia.nocookie.net/inazuma-eleven/images/1/1a/(TG)_Banjou_Kazumichi_sprite.png/revision/latest | O30: Inazuma Eleven Wiki · (TG) Banjou Kazumichi sprite.png · candidate (check image) | P30: Candidate URL — needs visual check
A31: Narukami Kenya | B31: Teikoku Gakuen | C31: Japan | D31: 79 | E31: OF | F31: Original / Season 1 | G31: Prototype (unverified) | H31: FALSE | I31: FALSE | J31: FALSE | K31: TRUE | L31: =IF(N31="","",IFERROR(IMAGE(N31,4,48,48),"")) | M31: =IF(B31="","",IFERROR(VLOOKUP(B31,'Team Lineups'!$A$2:$Q$123,17,FALSE),"")) -> https://inazuma-eleven.fandom.com/wiki/Teikoku_Gakuen | N31: https://static.wikia.nocookie.net/inazuma-eleven/images/b/bb/(TG)_Narukami_Kenya_sprite.png/revision/latest | O31: Inazuma Eleven Wiki · (TG) Narukami Kenya sprite.png · candidate (check image) | P31: Candidate URL — needs visual check
A32: Gojou Masaru | B32: Teikoku Gakuen | C32: Japan | D32: 78 | E32: DF | F32: Original / Season 1 | G32: Added (verify team/roster) | H32: FALSE | I32: TRUE | J32: FALSE | K32: FALSE | L32: =IF(N32="","",IFERROR(IMAGE(N32,4,48,48),"")) | M32: =IF(B32="","",IFERROR(VLOOKUP(B32,'Team Lineups'!$A$2:$Q$123,17,FALSE),"")) -> https://inazuma-eleven.fandom.com/wiki/Teikoku_Gakuen | N32: https://static.wikia.nocookie.net/inazuma-eleven/images/1/13/(TG)_Gojou_Masaru_sprite.png/revision/latest | O32: Inazuma Eleven Wiki · (TG) Gojou Masaru sprite.png · candidate (check image) | P32: Candidate URL — needs visual check
A33: Henmi Wataru | B33: Teikoku Gakuen | C33: Japan | D33: 80 | E33: DF, MF | F33: Original / Season 1 | G33: Prototype (unverified) | H33: FALSE | I33: TRUE | J33: TRUE | K33: FALSE | L33: =IF(N33="","",IFERROR(IMAGE(N33,4,48,48),"")) | M33: =IF(B33="","",IFERROR(VLOOKUP(B33,'Team Lineups'!$A$2:$Q$123,17,FALSE),"")) -> https://inazuma-eleven.fandom.com/wiki/Teikoku_Gakuen | N33: https://static.wikia.nocookie.net/inazuma-eleven/images/1/13/(TG)_Henmi_Wataru_sprite.png/revision/latest | O33: Inazuma Eleven Wiki · (TG) Henmi Wataru sprite.png · candidate (check image) | P33: Candidate URL — needs visual check
A34: Sakiyama Shuuji | B34: Teikoku Gakuen | C34: Japan | D34: 76 | E34: MF | F34: Original / Season 1 | G34: Wiki member; OVR/positions provisional | H34: FALSE | I34: FALSE | J34: TRUE | K34: FALSE | L34: =IF(N34="","",IFERROR(IMAGE(N34,4,48,48),"")) | M34: =IF(B34="","",IFERROR(VLOOKUP(B34,'Team Lineups'!$A$2:$Q$123,17,FALSE),"")) -> https://inazuma-eleven.fandom.com/wiki/Teikoku_Gakuen | N34: https://static.wikia.nocookie.net/inazuma-eleven/images/1/16/(TG)_Sakiyama_Shuuji_sprite.png/revision/latest | O34: Inazuma Eleven Wiki · (TG) Sakiyama Shuuji sprite.png · candidate (check image) | P34: Candidate URL — needs visual check
A35: Doumen Shuuichirou | B35: Teikoku Gakuen | C35: Japan | D35: 77 | E35: DF | F35: Original / Season 1 | G35: Prototype (unverified) | H35: FALSE | I35: TRUE | J35: FALSE | K35: FALSE | L35: =IF(N35="","",IFERROR(IMAGE(N35,4,48,48),"")) | M35: =IF(B35="","",IFERROR(VLOOKUP(B35,'Team Lineups'!$A$2:$Q$123,17,FALSE),"")) -> https://inazuma-eleven.fandom.com/wiki/Teikoku_Gakuen | N35: https://static.wikia.nocookie.net/inazuma-eleven/images/d/d3/(TG)_Doumen_Shuuichirou_sprite.png/revision/latest | O35: Inazuma Eleven Wiki · (TG) Doumen Shuuichirou sprite.png · candidate (check image) | P35: Candidate URL — needs visual check
A36: Jimon Daiki | B36: Teikoku Gakuen | C36: Japan | D36: 81 | E36: OF | F36: Original / Season 1 | G36: Prototype (unverified) | H36: FALSE | I36: FALSE | J36: FALSE | K36: TRUE | L36: =IF(N36="","",IFERROR(IMAGE(N36,4,48,48),"")) | M36: =IF(B36="","",IFERROR(VLOOKUP(B36,'Team Lineups'!$A$2:$Q$123,17,FALSE),"")) -> https://inazuma-eleven.fandom.com/wiki/Teikoku_Gakuen | N36: https://static.wikia.nocookie.net/inazuma-eleven/images/4/4a/(TG)_Jimon_Daiki_sprite.png/revision/latest | O36: Inazuma Eleven Wiki · (TG) Jimon Daiki sprite.png · candidate (check image) | P36: Candidate URL — needs visual check
A37: Kidou Yuuto | B37: Teikoku Gakuen | C37: Japan | D37: 94 | E37: MF, OF | F37: Original / Season 1 | G37: Prototype (unverified) | H37: FALSE | I37: FALSE | J37: TRUE | K37: TRUE | L37: =IF(N37="","",IFERROR(IMAGE(N37,4,48,48),"")) | M37: =IF(B37="","",IFERROR(VLOOKUP(B37,'Team Lineups'!$A$2:$Q$123,17,FALSE),"")) -> https://inazuma-eleven.fandom.com/wiki/Teikoku_Gakuen | N37: https://static.wikia.nocookie.net/inazuma-eleven/images/f/f9/(TG_IE2-IE3)_Kidou_Yuuto_sprite.png/revision/latest | O37: Inazuma Eleven Wiki · (TG IE2-IE3) Kidou Yuuto sprite.png | P37: Wiki page lists exact Teikoku uniform filename
A38: Sakuma Jirou | B38: Teikoku Gakuen | C38: Japan | D38: 86 | E38: MF, OF | F38: Original / Season 1 | G38: Prototype (unverified) | H38: FALSE | I38: FALSE | J38: TRUE | K38: TRUE | L38: =IF(N38="","",IFERROR(IMAGE(N38,4,48,48),"")) | M38: =IF(B38="","",IFERROR(VLOOKUP(B38,'Team Lineups'!$A$2:$Q$123,17,FALSE),"")) -> https://inazuma-eleven.fandom.com/wiki/Teikoku_Gakuen | N38: https://static.wikia.nocookie.net/inazuma-eleven/images/3/39/%28TG_IE2-IE3%29_Sakuma_Jirou_sprite.png/revision/latest?cb=20230827093642 | O38: Inazuma Eleven Wiki · (TG IE2-IE3) Sakuma Jirou sprite.png | P38: Exact user-supplied wiki sprite — correct team uniform | Q38: https://inazuma-eleven.fandom.com/wiki/Sakuma_Jirou
A39: Hyoudou Yuuhei | B39: Teikoku Gakuen | C39: Japan | D39: 78 | E39: GK, DF | F39: Original / Season 1 | G39: Wiki member; OVR/positions provisional | H39: TRUE | I39: TRUE | J39: FALSE | K39: FALSE | L39: =IF(N39="","",IFERROR(IMAGE(N39,4,48,48),"")) | M39: =IF(B39="","",IFERROR(VLOOKUP(B39,'Team Lineups'!$A$2:$Q$123,17,FALSE),"")) -> https://inazuma-eleven.fandom.com/wiki/Teikoku_Gakuen | N39: https://static.wikia.nocookie.net/inazuma-eleven/images/d/d2/(TG)_Hyoudou_Yuuhei_sprite.png/revision/latest | O39: Inazuma Eleven Wiki · (TG) Hyoudou Yuuhei sprite.png · candidate (check image) | P39: Candidate URL — needs visual check
A40: Ena Kazuki | B40: Teikoku Gakuen | C40: Japan | D40: 80 | E40: OF | F40: Original / Season 1 | G40: Wiki member; OVR/positions provisional | H40: FALSE | I40: FALSE | J40: FALSE | K40: TRUE | L40: =IF(N40="","",IFERROR(IMAGE(N40,4,48,48),"")) | M40: =IF(B40="","",IFERROR(VLOOKUP(B40,'Team Lineups'!$A$2:$Q$123,17,FALSE),"")) -> https://inazuma-eleven.fandom.com/wiki/Teikoku_Gakuen | N40: https://static.wikia.nocookie.net/inazuma-eleven/images/7/70/(TG)_Ena_Kazuki_sprite.png/revision/latest | O40: Inazuma Eleven Wiki · (TG) Ena Kazuki sprite.png · candidate (check image) | P40: Candidate URL — needs visual check
...

Sheet README
A1: INAZUMA ELEVEN — ANIME ROSTER EDITOR
A2: Coverage | B2: Ina7 live: 122 teams, 1,728 player-team memberships. Raimon now lists the original team, with Second Raimon separately; user-edited positions, aliases, and lineups are synced. Some image and emblem references remain provisional.
A3: Important | B3: Some entries/club assignments need verification; check 'Verification' column before using as canon.
A4: One row per team membership | B4: The same character can appear on different teams; each team membership and uniform remains a distinct row.
A5: Rating | B5: Suggested fictional 1–99 values, NOT game/anime official stats.
A6: Positions | B6: Only GK, DF, MF and OF. Comma-separated positions allow eligible multi-role players. OVR and some roles are fictional estimates.
A7: Position toggles | B7: Roster H–K = GK / DF / MF / OF flags. Keep these consistent with the comma-separated Positions column.
A8: Google Sheets multi-select | B8: Edit only GK/DF/MF/OF groups in column E; do not use old CB, LB, CM, ST etc as eligible groups.
A9: Nationality | B9: Tentative country/origin of the team, not verified personal citizenship; adjust per character.
A10: Sync to game | B10: Changes in this Google Sheet do not automatically update the bundled browser game. Download the full workbook as .xlsx; a new game build can incorporate the updated data.
A11: Scope | B11: 121 anime teams, including Young Inazuma separately from Raimon OB and 12 new Chrono Stone / movie teams. Game-only/temporary-exclusive players excluded from new squads.
B12: 122 anime team entries. Original Raimon retains its original-era roster; Second Raimon is a distinct anime team, and B Team (Raimon) remains separate. Three Fubuki forms are recorded under one canonical identity.
A13: Team Lineups | B13: 121 playable starting XIs. Some portraits and emblems remain unverified FilePath candidates; user-supplied exact sprites preserved.
B14: All team lineups repaired to use 11 legal positions after player TRUE/FALSE position edits; unverified portrait and emblem links are labelled.
B15: Export the full Google Sheet as one .xlsx workbook to reuse in the game importer when a future browser-game rebuild is requested. Separate CSV exports may not preserve tabs.
B16: FFI sprites: (TK) The Kingdom, (RM) Red Matador, (RG) Rose Griffon, and (B) Brockenborg. Three links were supplied directly; other generated CDN links need visual verification.
A18: ADDITIONS AUDIT | B18: GO / Ares / Orion expansion added 44 teams (18 GO, 11 Ares, 15 Orion). Original-series expansion added 17 before 3 were removed later. Badges are now populated for every remaining team using wiki emblem catalog names or prior user-provided URLs.
A19: Dropdown acceptance | B19: Extend the Roster native table 'Ina7RosterChips' Team DROPDOWN options (not only cell validation) and table range when needed. Confirm all team chips are valid.
A20: Player formatting | B20: Preserve the existing row styles, rating colors, team/nationality/arc/verification options, and GK/DF/MF/OF flags. Keep the Canonical Name identical for alternate appearances of the same character.
A21: Portraits and sources | B21: Roster M, N, O, P contain exact or candidate wiki image URL, source, verification status, and wiki filename; Portrait Gallery E/F are synchronized. User-provided confirmed images preserved. Match the jersey/team version, including nonpixelated images when suitable.
A22: Team setup | B22: Add Team Lineups badge URL and preview, roster-correct starting XI, formation/style, and preserve formation/style validations.
A23: Refresh the game | B23: Use .xlsx export and rebuild the packaged HTML game's embedded roster and lineups. Sheet editing alone does not change the shipped standalone browser game.
A24: ORIGINAL-SERIES ADDITIONS | B24: 14 original-series expansion teams remain after removing Aka Gumi, Shiro Gumi and Erabareta 11nin; all corresponding Roster, Portrait Gallery and Team Lineups rows have been deleted.
A26: Portrait status — October 2026 | B26: Team Wiki Page columns in Roster R and Portrait Gallery G reference Team Lineups. Team portrait URLs require visual verification where marked provisional. Deleted teams no longer appear.
A27: Portrait audit: confidence | B27: Only links with cited wiki sprite filenames are high-confidence candidates. Other inferred paths are explicitly labeled PROVISIONAL in Roster Sprite verification (O); a nonempty URL is not proof that a portrait loads or is the correct costume.
A28: Portrait audit: next step | B28: Verify rendered images for all provisional links, replace incorrect/broken URLs with exact images from each player's team's wiki page; retain team-specific sprites and align Portrait Gallery.
A29: Photo source workflow | B29: For team additions, collect team wiki page, exact team-character sprite image filename/URL, maintain portrait IMAGE formulas and gallery; never present inferred filenames as verified.
A31: CURRENT TEAM CLEANUP STATUS | B31: Original team removals remain applied (Aka Gumi, Shiro Gumi, Erabareta 11nin). 108 teams, 1,549 memberships, zero Gallery alignment errors, all starting XIs validated.
... A41: 2026-10-15 INDEX EVIDENCE | B41: Catalog references: https://inazuma-eleven.fandom.com/wiki/Category:Galaxy_sprites and https://inazuma-eleven.fandom.com/wiki/Category:Victory_Road_sprites. Exact filenames recorded in Roster P; CDN asset display remains to be checked.

Sheet Portrait Gallery
A1: Portrait | B1: Player | C1: Team | D1: OVR | E1: Image source | F1: Portrait URL | G1: Team Wiki Page
A2: =IF(F2="","",IFERROR(IMAGE(F2,4,48,48),"")) | B2: Endou Mamoru | C2: Raimon | D2: 94 | E2: Inazuma Eleven Wiki · (R IE2-IE3) Endou Mamoru sprite.png | F2: https://static.wikia.nocookie.net/inazuma-eleven/images/3/32/(R_IE2-IE3)_Endou_Mamoru_sprite.png/revision/latest | G2: =IF(C2="","",IFERROR(VLOOKUP(C2,'Team Lineups'!$A$2:$Q$123,17,FALSE),"")) -> https://inazuma-eleven.fandom.com/wiki/Raimon
A3: =IF(F3="","",IFERROR(IMAGE(F3,4,48,48),"")) | B3: Kazemaru Ichirouta | C3: Raimon | D3: 87 | E3: Inazuma Eleven Wiki · (R IE2-IE3) Kazemaru Ichirouta sprite.png | F3: https://static.wikia.nocookie.net/inazuma-eleven/images/7/72/(R_IE2-IE3)_Kazemaru_Ichirouta_sprite.png/revision/latest | G3: =IF(C3="","",IFERROR(VLOOKUP(C3,'Team Lineups'!$A$2:$Q$123,17,FALSE),"")) -> https://inazuma-eleven.fandom.com/wiki/Raimon
A4: =IF(F4="","",IFERROR(IMAGE(F4,4,48,48),"")) | B4: Kabeyama Heigorou | C4: Raimon | D4: 84 | E4: Inazuma Eleven Wiki · (R IE2-IE3) Kabeyama Heigorou sprite.png | F4: https://static.wikia.nocookie.net/inazuma-eleven/images/b/ba/(R_IE2-IE3)_Kabeyama_Heigorou_sprite.png/revision/latest | G4: =IF(C4="","",IFERROR(VLOOKUP(C4,'Team Lineups'!$A$2:$Q$123,17,FALSE),"")) -> https://inazuma-eleven.fandom.com/wiki/Raimon
A5: =IF(F5="","",IFERROR(IMAGE(F5,4,48,48),"")) | B5: Kageno Jin | C5: Raimon | D5: 76 | E5: Inazuma Eleven Wiki · (R IE2-IE3) Kageno Jin sprite.png | F5: https://static.wikia.nocookie.net/inazuma-eleven/images/9/9b/(R_IE2-IE3)_Kageno_Jin_sprite.png/revision/latest | G5: =IF(C5="","",IFERROR(VLOOKUP(C5,'Team Lineups'!$A$2:$Q$123,17,FALSE),"")) -> https://inazuma-eleven.fandom.com/wiki/Raimon
A6: =IF(F6="","",IFERROR(IMAGE(F6,4,48,48),"")) | B6: Kurimatsu Teppei | C6: Raimon | D6: 79 | E6: Inazuma Eleven Wiki · (R IE2-IE3) Kurimatsu Teppei sprite.png | F6: https://static.wikia.nocookie.net/inazuma-eleven/images/9/97/(R_IE2-IE3)_Kurimatsu_Teppei_sprite.png/revision/latest | G6: =IF(C6="","",IFERROR(VLOOKUP(C6,'Team Lineups'!$A$2:$Q$123,17,FALSE),"")) -> https://inazuma-eleven.fandom.com/wiki/Raimon
A7: =IF(F7="","",IFERROR(IMAGE(F7,4,48,48),"")) | B7: Handa Shinichi | C7: Raimon | D7: 77 | E7: Inazuma Eleven Wiki · (R IE2-IE3) Handa Shinichi sprite.png | F7: https://static.wikia.nocookie.net/inazuma-eleven/images/0/04/(R_IE2-IE3)_Handa_Shinichi_sprite.png/revision/latest | G7: =IF(C7="","",IFERROR(VLOOKUP(C7,'Team Lineups'!$A$2:$Q$123,17,FALSE),"")) -> https://inazuma-eleven.fandom.com/wiki/Raimon
A8: =IF(F8="","",IFERROR(IMAGE(F8,4,48,48),"")) | B8: Shourinji Ayumu | C8: Raimon | D8: 76 | E8: Inazuma Eleven Wiki · (R IE2-IE3) Shourinji Ayumu sprite.png | F8: https://static.wikia.nocookie.net/inazuma-eleven/images/4/41/(R_IE2-IE3)_Shourinji_Ayumu_sprite.png/revision/latest | G8: =IF(C8="","",IFERROR(VLOOKUP(C8,'Team Lineups'!$A$2:$Q$123,17,FALSE),"")) -> https://inazuma-eleven.fandom.com/wiki/Raimon
A9: =IF(F9="","",IFERROR(IMAGE(F9,4,48,48),"")) | B9: Shishido Sakichi | C9: Raimon | D9: 75 | E9: Inazuma Eleven Wiki · (R IE2-IE3) Shishido Sakichi sprite.png | F9: https://static.wikia.nocookie.net/inazuma-eleven/images/5/58/(R_IE2-IE3)_Shishido_Sakichi_sprite.png/revision/latest | G9: =IF(C9="","",IFERROR(VLOOKUP(C9,'Team Lineups'!$A$2:$Q$123,17,FALSE),"")) -> https://inazuma-eleven.fandom.com/wiki/Raimon
A10: =IF(F10="","",IFERROR(IMAGE(F10,4,48,48),"")) | B10: Matsuno Kuusuke | C10: Raimon | D10: 79 | E10: Inazuma Eleven Wiki · (R IE2-IE3) Matsuno Kuusuke sprite.png | F10: https://static.wikia.nocookie.net/inazuma-eleven/images/9/91/(R_IE2-IE3)_Matsuno_Kuusuke_sprite.png/revision/latest | G10: =IF(C10="","",IFERROR(VLOOKUP(C10,'Team Lineups'!$A$2:$Q$123,17,FALSE),"")) -> https://inazuma-eleven.fandom.com/wiki/Raimon
A11: =IF(F11="","",IFERROR(IMAGE(F11,4,48,48),"")) | B11: Gouenji Shuuya | C11: Raimon | D11: 95 | E11: Inazuma Eleven Wiki · (R IE2-IE3) Gouenji Shuuya sprite.png | F11: https://static.wikia.nocookie.net/inazuma-eleven/images/b/b8/(R_IE2-IE3)_Gouenji_Shuuya_sprite.png/revision/latest | G11: =IF(C11="","",IFERROR(VLOOKUP(C11,'Team Lineups'!$A$2:$Q$123,17,FALSE),"")) -> https://inazuma-eleven.fandom.com/wiki/Raimon
A12: =IF(F12="","",IFERROR(IMAGE(F12,4,48,48),"")) | B12: Someoka Ryuugo | C12: Raimon | D12: 84 | E12: Inazuma Eleven Wiki · (R IE2-IE3) Someoka Ryuugo sprite.png | F12: https://static.wikia.nocookie.net/inazuma-eleven/images/7/72/(R_IE2-IE3)_Someoka_Ryuugo_sprite.png/revision/latest | G12: =IF(C12="","",IFERROR(VLOOKUP(C12,'Team Lineups'!$A$2:$Q$123,17,FALSE),"")) -> https://inazuma-eleven.fandom.com/wiki/Raimon
A13: =IF(F13="","",IFERROR(IMAGE(F13,4,48,48),"")) | B13: Megane Kakeru | C13: Raimon | D13: 68 | E13: Inazuma Eleven Wiki · (R IE2-IE3) Megane Kakeru sprite.png | F13: https://static.wikia.nocookie.net/inazuma-eleven/images/2/2b/(R_IE2-IE3)_Megane_Kakeru_sprite.png/revision/latest | G13: =IF(C13="","",IFERROR(VLOOKUP(C13,'Team Lineups'!$A$2:$Q$123,17,FALSE),"")) -> https://inazuma-eleven.fandom.com/wiki/Raimon
... A1729: =IF(F1729="","",IFERROR(IMAGE(F1729,4,48,48),"")) | B1729: Megane Kakeru | C1729: Second Raimon | D1729: 68 | E1729: Verified direct image reference from Raimon; Second Raimon uniform variant not independently confirmed | F1729: https://static.wikia.nocookie.net/inazuma-eleven/images/2/2b/(R_IE2-IE3)_Megane_Kakeru_sprite.png/revision/latest | G1729: =IF(C1729="","",IFERROR(VLOOKUP(C1729,'Team Lineups'!$A$2:$Q$123,17,FALSE),"")) -> https://inazuma-eleven.fandom.com/wiki/Second_Raimon

Sheet Team Lineups
A1: Team | B1: Badge Preview | C1: Formation | D1: Style | E1: Status | F1: Slot 1 | G1: Slot 2 | H1: Slot 3 | I1: Slot 4 | J1: Slot 5 | K1: Slot 6 | L1: Slot 7 | M1: Slot 8 | N1: Slot 9 | O1: Slot 10 | P1: Slot 11 | Q1: Source / Notes | R1: Badge URL | S1: Badge status / source
A2: Raimon | B2: =IF(R2="","",IFERROR(IMAGE(R2,4,56,56),"")) | C2: 4-3-3 | D2: Joga Bonito | E2: Ready · 11 legal players | F2: GK: Endou Mamoru | G2: LB: Kazemaru Ichirouta | H2: LCB: Kabeyama Heigorou | I2: RCB: Domon Asuka | J2: RB: Kurimatsu Teppei | K2: LCM: Kidou Yuuto | L2: CCM: Ichinose Kazuya | M2: RCM: Handa Shinichi | N2: LW: Gouenji Shuuya | O2: ST: Someoka Ryuugo | P2: RW: Matsuno Kuusuke | Q2: https://inazuma-eleven.fandom.com/wiki/Raimon | R2: https://static.wikia.nocookie.net/inazuma-eleven/images/d/d0/Raimon_emblem.png/revision/latest | S2: Provisional wiki file mapping; image not checked
A3: Second Raimon | B3: =IF(R3="","",IFERROR(IMAGE(R3,4,56,56),"")) | C3: 4-3-3 | D3: Joga Bonito | E3: Ready · 11 legal anime members + reserves | F3: GK: Endou Mamoru | G3: LB: Kazemaru Ichirouta | H3: LCB: Kabeyama Heigorou | I3: RCB: Domon Asuka | J3: RB: Kurimatsu Teppei | K3: LCM: Kidou Yuuto | L3: CCM: Ichinose Kazuya | M3: RCM: Zaizen Touko | N3: LW: Gouenji Shuuya | O3: ST: Fubuki Shirou ("Atsuya") | P3: RW: Someoka Ryuugo | Q3: https://inazuma-eleven.fandom.com/wiki/Second_Raimon | R3: https://static.wikia.nocookie.net/inazuma-eleven/images/8/89/Second_Raimon_emblem_%28S%29.png/revision/latest?cb=20220301184145 | S3: Exact user-provided Second Raimon emblem URL
A4: Raimon A Team | B4: =IF(R4="","",IFERROR(IMAGE(R4,4,56,56),"")) | C4: 5-3-2 | D4: Joga Bonito | E4: Ready · original eleven | F4: GK: Endou Mamoru | G4: LWB: Kazemaru Ichirouta | H4: LCB: Kabeyama Heigorou | I4: CCB: Kageno Jin | J4: RCB: Shourinji Ayumu | K4: RWB: Kurimatsu Teppei | L4: LCM: Handa Shinichi | M4: CM: Shishido Sakichi | N4: RCM: Matsuno Kuusuke | O4: LST: Gouenji Shuuya | P4: RST: Someoka Ryuugo | Q4: https://inazuma-eleven.fandom.com/wiki/Raimon | R4: https://static.wikia.nocookie.net/inazuma-eleven/images/d/d0/Raimon_emblem.png/revision/latest | S4: Same badge as original Raimon; team-specific entry
A5: Teikoku Gakuen | B5: =IF(R5="","",IFERROR(IMAGE(R5,4,56,56),"")) | C5: 5-3-2 | D5: Catenaccio | E5: Ready · 11 legal players | F5: GK: Genda Koujirou | G5: LWB: Henmi Wataru | H5: LCB: Banjou Kazumichi | I5: CCB: Gojou Masaru | J5: RCB: Doumen Shuuichirou | K5: RWB: Oono Densuke | L5: LCM: Kidou Yuuto | M5: CM: Fudou Akio | N5: RCM: Sakiyama Shuuji | O5: LST: Sakuma Jirou | P5: RST: Jimon Daiki | Q5: https://inazuma-eleven.fandom.com/wiki/Teikoku_Gakuen | R5: https://static.wikia.nocookie.net/inazuma-eleven/images/3/34/Teikoku_Gakuen_emblem.png/revision/latest | S5: Provisional wiki file mapping; image not checked
A6: Occult | B6: =IF(R6="","",IFERROR(IMAGE(R6,4,56,56),"")) | C6: 3-5-2 | D6: Counter-Attacking | E6: Ready · 11 legal players | F6: GK: Nata Juuzou | G6: LCB: Sanzu Wataru | H6: CCB: Yanagida Shigeru | I6: RCB: Furan Ken | J6: LM: Yuukoku Hiroyuki | K6: LCM: Shikabane Fujimi | L6: CAM: Reigen Michihisa | M6: RCM: Kinoi Mami | N6: RM: Yatsuhaka Tataru | O6: LST: Tsukimura Kenichi | P6: RST: Burado Kiba | Q6: https://inazuma-eleven.fandom.com/wiki/Occult | R6: https://static.wikia.nocookie.net/inazuma-eleven/images/d/dd/Occult_emblem.png/revision/latest | S6: Provisional wiki file mapping; image not checked
A7: Nose | B7: =IF(R7="","",IFERROR(IMAGE(R7,4,56,56),"")) | C7: 4-3-3 | D7: Direct Football | E7: Ready · 11 legal players | F7: GK: Inokuchi Hyougo | G7: LB: Torii Ryouta | H7: LCB: Shishiou Kou | I7: RCB: Ushio Kuuya | J7: RB: Kaeruda Tatsuhito | K7: LCM: Oowashi Seiji | L7: CCM: Kame Leon | M7: RCM: Koara Noboru | N7: LW: Suizenji Chiita | O7: ST: Pan Takeo | P7: RW: Hebimaru Shouma | Q7: https://inazuma-eleven.fandom.com/wiki/Nose | R7: https://static.wikia.nocookie.net/inazuma-eleven/images/b/b3/Nose_emblem.png/revision/latest | S7: Provisional wiki file mapping; image not checked
A8: Mikage Sennou | B8: =IF(R8="","",IFERROR(IMAGE(R8,4,56,56),"")) | C8: 4-4-2 | D8: Tiki-Taka | E8: Ready · 11 legal players | F8: GK: Sugimori Takeshi | G8: LB: Inada Nori | H8: LCB: Murobushi Kyou | I8: RCB: Hanaoka Tsuyoshi | J8: RB: Hiroyama Yuu | K8: LM: Yamagishi Seri | L8: LCM: Sangou Baku | M8: RCM: Fujimaru Kei | N8: RM: Terakawa Iwao | O8: LST: Mizubuchi Nashi | P8: RST: Nagatomo Sou | Q8: https://inazuma-eleven.fandom.com/wiki/Mikage_Sennou | R8: https://static.wikia.nocookie.net/inazuma-eleven/images/b/b7/Mikage_Sennou_emblem.png/revision/latest | S8: Provisional wiki file mapping; image not checked
A9: Shuuyou Meito Gakuen | B9: =IF(R9="","",IFERROR(IMAGE(R9,4,56,56),"")) | C9: 4-4-2 | D9: Joga Bonito | E9: Ready · 11 position-eligible players | F9: GK: Aidoru Sou | G9: LB: Karisawa Sou | H9: LCB: Muteki Hideo | I9: RCB: Noberu Raito | J9: RB: Sujimichi Tetsuo | K9: LM: Geimu Konomu | L9: LCM: Robo Gouki | M9: RCM: Onotomo Haru | N9: RM: Onra Itsuki | O9: LST: Touma Souta | P9: RST: Akeido Tatsuhito | Q9: https://inazuma-eleven.fandom.com/wiki/Shuuyou_Meito_Gakuen | R9: https://static.wikia.nocookie.net/inazuma-eleven/images/d/d4/Shuuyou_Meito_Gakuen_emblem.png/revision/latest | S9: Provisional wiki file mapping; image not checked
A10: Sengoku Igajima | B10: =IF(R10="","",IFERROR(IMAGE(R10,4,56,56),"")) | C10: 3-4-3 | D10: Counter-Attacking | E10: Ready · 11 position-eligible players | F10: GK: Momochi Santa | G10: LCB: Ishikawa Goeta | H10: CCB: Jiraiya Gamasuke | I10: RCB: Kousaka Jin | J10: LM: Yagyuu Juurou | K10: LCM: Fuuma Koheita | L10: RCM: Sarutobi Sanosuke | M10: RM: Kouga Gen | N10: LW: Kirigakure Saiji | O10: ST: Hachiya Yasaburou | P10: RW: Ideura Kiyomori | Q10: https://inazuma-eleven.fandom.com/wiki/Sengoku_Igajima | R10: https://static.wikia.nocookie.net/inazuma-eleven/images/9/9c/Sengoku_Igajima_emblem.png/revision/latest | S10: Provisional wiki file mapping; image not checked
A11: Senbayama | B11: =IF(R11="","",IFERROR(IMAGE(R11,4,56,56),"")) | C11: 3-4-3 | D11: Catenaccio | E11: Ready · 11 position-eligible players | F11: GK: Makiya Hiroshi | G11: LCB: Shiotani Hiro | H11: CCB: Serizawa Kazunori | I11: RCB: Sumino Eisuke | J11: LM: Harano Tooru | K11: LCM: Oogoi Noboru | L11: RCM: Ikui Shouji | M11: RM: Yamane You | N11: LW: Tanushimaru Shigeki | O11: ST: Fukui Sakuhei | P11: RW: Negami Daichi | Q11: https://inazuma-eleven.fandom.com/wiki/Senbayama | R11: https://static.wikia.nocookie.net/inazuma-eleven/images/e/e8/Senbayama_emblem.png/revision/latest | S11: Provisional wiki file mapping; image not checked
A12: Kidokawa Seishuu | B12: =IF(R12="","",IFERROR(IMAGE(R12,4,56,56),"")) | C12: 4-3-3 | D12: Direct Football | E12: Ready · 11 legal players | F12: GK: Nanzan Yowami | G12: LB: Nishigaki Mamoru | H12: LCB: Kurobe Ritsuki | I12: RCB: Megawa Akihi | J12: RB: Mitsumune Dan | K12: LCM: Tobiyama Dan | L12: CCM: Yakata Naoto | M12: RCM: Mogi Sakito | N12: LW: Mukata Masaru | O12: ST: Mukata Tomo | P12: RW: Mukata Tsutomu | Q12: https://inazuma-eleven.fandom.com/wiki/Kidokawa_Seishuu | R12: https://static.wikia.nocookie.net/inazuma-eleven/images/a/ad/Kidokawa_Seishuu_emblem.png/revision/latest | S12: Provisional wiki file mapping; image not checked
A13: Zeus | B13: =IF(R13="","",IFERROR(IMAGE(R13,4,56,56),"")) | C13: 4-4-2 | D13: Tiki-Taka | E13: Ready · 11 legal players | F13: GK: Poseidon | G13: LB: Ares | H13: LCB: Heracles | I13: RCB: Dio | J13: RB: Hephais | K13: LM: Aphrodi | L13: LCM: Hera | M13: RCM: Hermes | N13: RM: Athena | O13: LST: Demeter | P13: RST: Apollon | Q13: https://inazuma-eleven.fandom.com/wiki/Zeus | R13: https://static.wikia.nocookie.net/inazuma-eleven/images/e/e0/Zeus_emblem.png/revision/latest | S13: Provisional wiki file mapping; image not checked
... A123: Young Inazuma | B123: =IF(R123="","",IFERROR(IMAGE(R123,4,56,56),"")) | C123: 5-3-2 | D123: Catenaccio | E123: Ready · 11 anime-documented prime-era players | F123: GK: Hibiki Seigou | G123: LWB: Ukishima Kazuto | H123: LCB: Kamimura Kirito | I123: CCB: Aida Chikara | J123: RCB: Batora Manabu | K123: RWB: Nakama You | L123: LCM: Ikari Gengorou | M123: CM: Teira Tamotsu | N123: RCM: Tamiyama You | O123: LST: Sugata Iwao | P123: RST: Biruda Kouichi | Q123: https://inazuma-eleven.fandom.com/wiki/Young_Inazuma | R123: https://static.wikia.nocookie.net/inazuma-eleven/images/b/ba/Young_Inazuma_emblem_%28VR%29.png/revision/latest?cb=20251118144157 | S123: Exact user-provided Young Inazuma emblem

Sheet Formation Templates
A1: Formation | B1: Slot order | C1: Position label | D1: Position group | E1: X % | F1: Y %
A2: 4-3-3 | B2: 1 | C2: GK | D2: GK | E2: 50 | F2: 90
A3: 4-3-3 | B3: 2 | C3: LB | D3: DF | E3: 15 | F3: 72
A4: 4-3-3 | B4: 3 | C4: LCB | D4: DF | E4: 38 | F4: 75
A5: 4-3-3 | B5: 4 | C5: RCB | D5: DF | E5: 62 | F5: 75
A6: 4-3-3 | B6: 5 | C6: RB | D6: DF | E6: 85 | F6: 72
A7: 4-3-3 | B7: 6 | C7: LCM | D7: MF | E7: 24 | F7: 48
A8: 4-3-3 | B8: 7 | C8: CCM | D8: MF | E8: 50 | F8: 53
A9: 4-3-3 | B9: 8 | C9: RCM | D9: MF | E9: 76 | F9: 48
A10: 4-3-3 | B10: 9 | C10: LW | D10: OF | E10: 20 | F10: 24
A11: 4-3-3 | B11: 10 | C11: ST | D11: OF | E11: 50 | F11: 19
A12: 4-3-3 | B12: 11 | C12: RW | D12: OF | E12: 80 | F12: 24
... A89: 4-2-4 | B89: 11 | C89: RW | D89: OF | E89: 87 | F89: 22
